<?xml version="1.0" ?>
<robot name="robot_to_export" xmlns:xacro="http://www.ros.org/wiki/xacro">


<!-- Define materials -->
<material name="wood">
  <color rgba="0.588 0.435 0.200 1.000"/>
</material>


<!-- Define the links -->

<link name="base_link">
  <inertial>
    <origin xyz="0.06959999984396244 0.03221502682625722 -0.05238610106605037" rpy="0 0 0"/>
    <mass value="7.199217531279626"/>
    <inertia ixx="0.013612" iyy="0.011302" izz="0.016116" ixy="0.0" iyz="-0.000837" ixz="-0.0"/>
  </inertial>
  <visual>
    <origin xyz="0 0 0" rpy="0 0 0"/>
    <geometry>
      <mesh filename="package://robot_to_export_description/meshes/base_link.stl" scale="0.001 0.001 0.001"/>
    </geometry>
    <material name="wood"/>
  </visual>
  <collision>
    <origin xyz="0 0 0" rpy="0 0 0"/>
    <geometry>
      <mesh filename="package://robot_to_export_description/meshes/base_link.stl" scale="0.001 0.001 0.001"/>
    </geometry>
  </collision>
</link>

<link name="hip-thigh-joint_1">
  <inertial>
    <origin xyz="0.02747761997112301 -7.148793887779697e-05 0.03529738098375114" rpy="0 0 0"/>
    <mass value="0.37008143562789914"/>
    <inertia ixx="0.001023" iyy="0.001077" izz="0.001036" ixy="1e-06" iyz="1e-06" ixz="-0.000317"/>
  </inertial>
  <visual>
    <origin xyz="-0.0696 -0.029307 0.001" rpy="0 0 0"/>
    <geometry>
      <mesh filename="package://robot_to_export_description/meshes/hip-thigh-joint_1.stl" scale="0.001 0.001 0.001"/>
    </geometry>
    <material name="wood"/>
  </visual>
  <collision>
    <origin xyz="-0.0696 -0.029307 0.001" rpy="0 0 0"/>
    <geometry>
      <mesh filename="package://robot_to_export_description/meshes/hip-thigh-joint_1.stl" scale="0.001 0.001 0.001"/>
    </geometry>
  </collision>
</link>

<link name="thigh_1">
  <inertial>
    <origin xyz="0.04834399984546503 -0.04326444191945761 -0.0003808122135104397" rpy="0 0 0"/>
    <mass value="7.995931898494293"/>
    <inertia ixx="0.150858" iyy="0.013583" izz="0.148494" ixy="-0.011461" iyz="0.000132" ixz="2.6e-05"/>
  </inertial>
  <visual>
    <origin xyz="-0.1386 -0.029307 -0.069" rpy="0 0 0"/>
    <geometry>
      <mesh filename="package://robot_to_export_description/meshes/thigh_1.stl" scale="0.001 0.001 0.001"/>
    </geometry>
    <material name="wood"/>
  </visual>
  <collision>
    <origin xyz="-0.1386 -0.029307 -0.069" rpy="0 0 0"/>
    <geometry>
      <mesh filename="package://robot_to_export_description/meshes/thigh_1.stl" scale="0.001 0.001 0.001"/>
    </geometry>
  </collision>
</link>

<link name="shin_1">
  <inertial>
    <origin xyz="0.04888140805528815 -0.12357772921141474 -0.00032553364531962004" rpy="0 0 0"/>
    <mass value="9.353708405648327"/>
    <inertia ixx="0.506763" iyy="0.016179" izz="0.504244" ixy="-0.008928" iyz="0.000376" ixz="2.5e-05"/>
  </inertial>
  <visual>
    <origin xyz="-0.1586 0.560693 -0.069" rpy="0 0 0"/>
    <geometry>
      <mesh filename="package://robot_to_export_description/meshes/shin_1.stl" scale="0.001 0.001 0.001"/>
    </geometry>
    <material name="wood"/>
  </visual>
  <collision>
    <origin xyz="-0.1586 0.560693 -0.069" rpy="0 0 0"/>
    <geometry>
      <mesh filename="package://robot_to_export_description/meshes/shin_1.stl" scale="0.001 0.001 0.001"/>
    </geometry>
  </collision>
</link>

<joint name="hip_pitch" type="continuous">
  <origin xyz="0.0696 0.029307 -0.001" rpy="0 0 0"/>
  <parent link="base_link"/>
  <child link="hip-thigh-joint_1"/>
  <axis xyz="0.0 -0.0 1.0"/>
</joint>

<joint name="hip_roll" type="continuous">
  <origin xyz="0.069 0.0 0.07" rpy="0 0 0"/>
  <parent link="hip-thigh-joint_1"/>
  <child link="thigh_1"/>
  <axis xyz="1.0 0.0 0.0"/>
</joint>

<joint name="knee_roll" type="continuous">
  <origin xyz="0.02 -0.59 0.0" rpy="0 0 0"/>
  <parent link="thigh_1"/>
  <child link="shin_1"/>
  <axis xyz="1.0 0.0 0.0"/>
</joint>

</robot>
